Workbook

Sheet READ_ME
A1: AI Acquisition Premium Study - Master Workbook
A2: Independent student research project, 2026. Hand-selected sample of 55 US public technology acquisitions (2015-2025) built from SEC filings and company press releases.
A4: Tabs
A5: Deal_Dataset: every deal, inputs in blue (from filings), multiples/growth/premium computed by live formulas in black.
A6: AI_Coding: the 18 companies classified blind by two coders, plus the final adjudicated label.
A7: Summary: sample counts and AI vs non-AI comparison (live formulas off Deal_Dataset).
A8: Regression_Results: exploratory statistical results (computed in Python, pasted as values).
A9: Sample_Waterfall: how 55 deals become the 35-deal EV/Revenue sample.
A11: Key result
A12: No evidence that AI-enabled targets traded at higher EV/Revenue multiples in this sample. Only 2-3 strict AI-native targets exist in the sample, so the pre-registered test could not be run; the result is exploratory, not definitive.
A14: Caveats
A15: 1. Sample is hand-picked (well-known deals), not a systematic universe. 2. EV is used only when company-stated or bridgeable from filings; otherwise blank. 3. Blank = not found in filings (never estimated). 4. No causal claims.
... A17: Units: $mm unless stated. Multiples in x. Premiums and growth as %.

Sheet Deal_Dataset
A1: Deal ID | B1: Target | C1: Buyer | D1: Announced | E1: Buyer type | F1: Sector | G1: Offer price ($/sh) | H1: Unaffected price ($/sh) | I1: Enterprise value ($mm) | J1: EV basis | K1: LTM revenue ($mm) | L1: Prior-year LTM revenue ($mm) | M1: LTM EBITDA ($mm) | N1: EV / Revenue (x) | O1: Revenue growth (%) | P1: EBITDA margin (%) | Q1: EV / EBITDA (x) | R1: 1-day premium (%) | S1: AI intensity (0-3) | T1: Broad AI (>=1) | U1: Strict AI (>=2) | V1: In EV/Rev sample | W1: In premium sample | X1: Data quality | Y1: Source URL | Z1: Notes
A2: L01 | B2: Informatica Corp | C2: Permira funds + CPPIB | D2: 2015-04-07 | E2: sponsor | F2: Infrastructure Software | G2: 48.75 | J2: undisclosed | K2: 1047.954 | L2: 948.171 | M2: 207.679 | N2: =IF(AND(ISNUMBER(I2),ISNUMBER(K2),K2>0),I2/K2,"") | O2: =IF(AND(ISNUMBER(K2),ISNUMBER(L2),L2>0),K2/L2-1,"") -> 0.10523735 | P2: =IF(AND(ISNUMBER(M2),ISNUMBER(K2),K2>0),M2/K2,"") -> 0.19817568 | Q2: =IF(AND(ISNUMBER(I2),ISNUMBER(M2),M2>0),I2/M2,"") | R2: =IF(AND(ISNUMBER(G2),ISNUMBER(H2),H2>0),G2/H2-1,"") | S2: 1 | T2: =IF(ISNUMBER(S2),IF(S2>=1,1,0),"") -> 1 | U2: =IF(ISNUMBER(S2),IF(S2>=2,1,0),"") -> 0 | V2: 0 | W2: 0 | X2: A | Y2: https://www.sec.gov/Archives/edgar/data/0001080099/000104746915004851/a2224711zdefm14a.htm | Z2: Headline USD 5.3bn is from the 2015-04-07 press release ('Transaction Valued at Approximately US$5.3 Billion or US$48.75 Per Share'); release does not label it equity or enterprise, so htype=consideration; equity/EV not stated in text read. Closing date 2015-08-06 from Informatica completion release (8-K). Ticker not extracted from filing text (cover page tool output omitted symbol); INFA per registrant convention. Buyer is UK-based Permira with Canadian CPPIB (consortium); bc=GB is a choice. Unaffected price not stated in text read; note Jan 23, 2015 reference date suggests earlier takeover speculation. DEFM14A only partially read (first ~100k chars + one further slice).
A3: L05 | B3: Cvent Inc | C3: Vista Equity Partners | D3: 2016-04-18 | E3: sponsor | F3: Application Software | G3: 36 | I3: 1504.539 | J3: calculated_from_bridge | K3: 187.716 | L3: 142.245 | M3: 3.723 | N3: =IF(AND(ISNUMBER(I3),ISNUMBER(K3),K3>0),I3/K3,"") -> 8.0149747 | O3: =IF(AND(ISNUMBER(K3),ISNUMBER(L3),L3>0),K3/L3-1,"") -> 0.31966677 | P3: =IF(AND(ISNUMBER(M3),ISNUMBER(K3),K3>0),M3/K3,"") -> 0.019833152 | Q3: =IF(AND(ISNUMBER(I3),ISNUMBER(M3),M3>0),I3/M3,"") -> 404.12006 | R3: =IF(AND(ISNUMBER(G3),ISNUMBER(H3),H3>0),G3/H3-1,"") | S3: 0 | T3: =IF(ISNUMBER(S3),IF(S3>=1,1,0),"") -> 0 | U3: =IF(ISNUMBER(S3),IF(S3>=2,1,0),"") -> 0 | V3: 1 | W3: 0 | X3: A | Y3: https://www.sec.gov/Archives/edgar/data/0001122897/000119312516543979/d183876dex991.htm | Z3: Press release: 'total value of approximately $1.65 billion' (treated as equity). Merger agreement dated 2016-04-17 per DEFM14A. Closing 2016-11-29 per 8-K Item 2.01. Unaffected dollar price not located in text read. Ticker not extracted from filing text.
A4: L04 | B4: Marketo Inc | C4: Vista Equity Partners | D4: 2016-05-31 | E4: sponsor | F4: Application Software | G4: 35.25 | I4: 1697.253 | J4: calculated_from_bridge | K4: 226.085 | L4: 163.662 | M4: -52.642 | N4: =IF(AND(ISNUMBER(I4),ISNUMBER(K4),K4>0),I4/K4,"") -> 7.5071455 | O4: =IF(AND(ISNUMBER(K4),ISNUMBER(L4),L4>0),K4/L4-1,"") -> 0.38141413 | P4: =IF(AND(ISNUMBER(M4),ISNUMBER(K4),K4>0),M4/K4,"") -> -0.23284163 | Q4: =IF(AND(ISNUMBER(I4),ISNUMBER(M4),M4>0),I4/M4,"") | R4: =IF(AND(ISNUMBER(G4),ISNUMBER(H4),H4>0),G4/H4-1,"") | S4: 1 | T4: =IF(ISNUMBER(S4),IF(S4>=1,1,0),"") -> 1 | U4: =IF(ISNUMBER(S4),IF(S4>=2,1,0),"") -> 0 | V4: 1 | W4: 0 | X4: B | Y4: https://www.sec.gov/Archives/edgar/data/0001490660/000104746916013522/a2228833zex-99_1.htm | Z4: Final price $35.25 per share (not $34.25). Press release 2016-05-31: 'total value of approximately $1.79 billion' for all outstanding shares (treated as equity value). DEFM14A states merger agreement dated May 27, 2016 (announcement May 31). Closing 2016-08-16 per 8-K Item 2.01. Unaffected dollar price not located in text read. Ticker not extracted from filing text.
A5: L03 | B5: Demandware Inc | C5: Salesforce.com Inc | D5: 2016-06-01 | E5: strategic | F5: Application Software | G5: 75 | I5: 2800 | J5: reported | K5: 254.083 | L5: 178.255 | M5: -29.422 | N5: =IF(AND(ISNUMBER(I5),ISNUMBER(K5),K5>0),I5/K5,"") -> 11.020021 | O5: =IF(AND(ISNUMBER(K5),ISNUMBER(L5),L5>0),K5/L5-1,"") -> 0.42539059 | P5: =IF(AND(ISNUMBER(M5),ISNUMBER(K5),K5>0),M5/K5,"") -> -0.11579681 | Q5: =IF(AND(ISNUMBER(I5),ISNUMBER(M5),M5>0),I5/M5,"") | R5: =IF(AND(ISNUMBER(G5),ISNUMBER(H5),H5>0),G5/H5-1,"") | S5: 0 | T5: =IF(ISNUMBER(S5),IF(S5>=1,1,0),"") -> 0 | U5: =IF(ISNUMBER(S5),IF(S5>=2,1,0),"") -> 0 | V5: 1 | W5: 0 | X5: B | Y5: https://www.sec.gov/Archives/edgar/data/0001301031/000119312516609202/d160431d8k.htm | Z5: Both Salesforce press release and Demandware 8-K say 'approximately $2.8 billion (net of cash acquired)', i.e. company-stated net-of-cash figure, treated as EV (evq B) - equity value not stated. Merger agreement dated 2016-05-31; structured as tender offer (no DEFM14A). Closing 2016-07-11 per Salesforce completion release. Premium / unaffected price not found (Schedule 14D-9 not retrieved; search budget exhausted). Ticker not extracted from filing text.
A6: L02 | B6: Qlik Technologies Inc | C6: Thoma Bravo | D6: 2016-06-02 | E6: sponsor | F6: Application Software | G6: 30.5 | J6: undisclosed | K6: 630.498 | L6: 565.949 | M6: 3.829 | N6: =IF(AND(ISNUMBER(I6),ISNUMBER(K6),K6>0),I6/K6,"") | O6: =IF(AND(ISNUMBER(K6),ISNUMBER(L6),L6>0),K6/L6-1,"") -> 0.11405445 | P6: =IF(AND(ISNUMBER(M6),ISNUMBER(K6),K6>0),M6/K6,"") -> 0.0060729772 | Q6: =IF(AND(ISNUMBER(I6),ISNUMBER(M6),M6>0),I6/M6,"") | R6: =IF(AND(ISNUMBER(G6),ISNUMBER(H6),H6>0),G6/H6-1,"") | S6: 0 | T6: =IF(ISNUMBER(S6),IF(S6>=1,1,0),"") -> 0 | U6: =IF(ISNUMBER(S6),IF(S6>=2,1,0),"") -> 0 | V6: 0 | W6: 0 | X6: A | Y6: https://www.sec.gov/Archives/edgar/data/0001305294/000119312516642539/d212251ddefm14a.htm | Z6: Headline ~USD 3.0bn from DEFA14A 'valued at approximately $3.0 billion' (unlabeled). Merger agreement dated 2016-06-02 per DEFM14A. Closing 2016-08-22 per Qlik 8-K Item 2.01 (a Thoma Bravo web page label shows Aug 29, 2016; used the SEC 8-K). Unaffected reference is a 10-day average ($21.83), not a single-day close, so un_px and un_date left null. Ticker not extracted from filing text. D&A from cash flow statement lines; Q1'16 10-Q lists no short-term investments.
A7: L08 | B7: MuleSoft, Inc. | C7: Salesforce.com, inc. | D7: 2018-03-20 | E7: strategic | F7: Infrastructure Software | G7: 44.89 | H7: 33.03 | I7: 6500 | J7: reported | K7: 296.456 | L7: 187.747 | M7: -75.962 | N7: =IF(AND(ISNUMBER(I7),ISNUMBER(K7),K7>0),I7/K7,"") -> 21.925682 | O7: =IF(AND(ISNUMBER(K7),ISNUMBER(L7),L7>0),K7/L7-1,"") -> 0.57901857 | P7: =IF(AND(ISNUMBER(M7),ISNUMBER(K7),K7>0),M7/K7,"") -> -0.25623364 | Q7: =IF(AND(ISNUMBER(I7),ISNUMBER(M7),M7>0),I7/M7,"") | R7: =IF(AND(ISNUMBER(G7),ISNUMBER(H7),H7>0),G7/H7-1,"") -> 0.35906751 | S7: 0 | T7: =IF(ISNUMBER(S7),IF(S7>=1,1,0),"") -> 0 | U7: =IF(ISNUMBER(S7),IF(S7>=2,1,0),"") -> 0 | V7: 1 | W7: 1 | X7: B | Y7: https://www.sec.gov/Archives/edgar/data/0001374684/000119312518089357/d554902dex991.htm | Z7: Consideration $36.00 cash + 0.0711 CRM shares; $44.89 is the implied value at Salesforce's 3/19/2018 close per 8-K Ex 99.1. EV approx $6.5bn is company-stated (press release); equity value not stated. VWAP is one-month (not strictly 30-day) per SC 14D-9 (https://www.sec.gov/Archives/edgar/data/1374684/000119312518104052/d560854dsc14d9.htm). Shares outstanding 3/28/2018: 94,416,981 Class A + 39,145,184 Class B (not fully diluted). Closing 2018-05-02 per Salesforce press release dateline. Ticker MULE per 10-K XBRL cover. Structure was tender offer, no DEFM14A. Deal pre-dates full stock-price drift; Salesforce stock-component value fluctuates.
A8: L07 | B8: Imperva, Inc. | C8: Thoma Bravo | D8: 2018-10-10 | E8: sponsor | F8: Cybersecurity | G8: 55.75 | H8: 43.06 | J8: undisclosed | K8: 344.017 | L8: 293.552 | M8: -0.355 | N8: =IF(AND(ISNUMBER(I8),ISNUMBER(K8),K8>0),I8/K8,"") | O8: =IF(AND(ISNUMBER(K8),ISNUMBER(L8),L8>0),K8/L8-1,"") -> 0.17191162 | P8: =IF(AND(ISNUMBER(M8),ISNUMBER(K8),K8>0),M8/K8,"") -> -0.0010319257 | Q8: =IF(AND(ISNUMBER(I8),ISNUMBER(M8),M8>0),I8/M8,"") | R8: =IF(AND(ISNUMBER(G8),ISNUMBER(H8),H8>0),G8/H8-1,"") -> 0.29470506 | S8: 0 | T8: =IF(ISNUMBER(S8),IF(S8>=1,1,0),"") -> 0 | U8: =IF(ISNUMBER(S8),IF(S8>=2,1,0),"") -> 0 | V8: 0 | W8: 1 | X8: A | Y8: https://www.sec.gov/Archives/edgar/data/0001364962/000119312518343681/d651525ddefm14a.htm | Z8: Offer is $55.75 (DEFM14A and 8-K Ex.99.1). Headline 'valued at approximately $2.1 billion' per press release (8-K Ex 99.1: https://www.sec.gov/Archives/edgar/data/0001364962/000119312518296463/d608301dex991.htm); DEFM14A says funding of approx $2.1bn covers stockholder and equity award payments plus cash on hand; equity vs enterprise basis not specified so htype set to consideration; eq and ev not stated -> null. Debt: no debt line item on 6/30/2018 balance sheet, set 0. Press release states no premium; premiums are from DEFM14A. Closing 2019-01-10 per 8-K Ex 99.1 (https://www.sec.gov/Archives/edgar/data/1364962/000119312519005808/d669134dex991.htm). Buyer country US not stated in filings (Thoma Bravo described only as PE firm); US per Thoma Bravo being a US-based PE firm (not verified in a filing in this pass). Ticker from 10-Q XBRL cover.
A9: L06 | B9: Apptio Inc | C9: Vista Equity Partners | D9: 2018-11-11 | E9: sponsor | F9: Application Software | G9: 38 | I9: 1794.728 | J9: calculated_from_bridge | K9: 224.705 | L9: 180.472 | M9: -14.709 | N9: =IF(AND(ISNUMBER(I9),ISNUMBER(K9),K9>0),I9/K9,"") -> 7.9870408 | O9: =IF(AND(ISNUMBER(K9),ISNUMBER(L9),L9>0),K9/L9-1,"") -> 0.24509619 | P9: =IF(AND(ISNUMBER(M9),ISNUMBER(K9),K9>0),M9/K9,"") -> -0.065459158 | Q9: =IF(AND(ISNUMBER(I9),ISNUMBER(M9),M9>0),I9/M9,"") | R9: =IF(AND(ISNUMBER(G9),ISNUMBER(H9),H9>0),G9/H9-1,"") | S9: 0 | T9: =IF(ISNUMBER(S9),IF(S9>=1,1,0),"") -> 0 | U9: =IF(ISNUMBER(S9),IF(S9>=2,1,0),"") -> 0 | V9: 1 | W9: 0 | X9: B | Y9: https://www.sec.gov/Archives/edgar/data/0001419625/000119312518345430/d584060ddefm14a.htm | Z9: Final price $38.00 per share (not $40). Value 'approximately $1.94 billion' as quoted from the Apptio press release (page retrieved was a DEFA14A containing a quoted complaint); not labeled equity vs EV, treated as equity. Press release 2018-11-11; merger agreement dated 2018-11-09. Closing 2019-01-10 per 8-K Item 2.01. fq=B because operating-income LTM mixes bases: FY2017 10-K is pre-ASC 606 while 2018 10-Q and its 2017 comparatives are restated (9M'17 operating loss (18,519) in 2018 10-Q vs (19,101) in original 2017 10-Q); revenue unaffected. Convertible notes carried net of discount (109,772K). Ticker not extracted from filing text.
A10: L13 | B10: Ultimate Software Group, Inc. | C10: Hellman & Friedman (investor group) | D10: 2019-02-04 | E10: sponsor | F10: Application Software | G10: 331.5 | H10: 277.83 | J10: undisclosed | K10: 1140.546 | L10: 940.729 | M10: 129.815 | N10: =IF(AND(ISNUMBER(I10),ISNUMBER(K10),K10>0),I10/K10,"") | O10: =IF(AND(ISNUMBER(K10),ISNUMBER(L10),L10>0),K10/L10-1,"") -> 0.21240655 | P10: =IF(AND(ISNUMBER(M10),ISNUMBER(K10),K10>0),M10/K10,"") -> 0.11381829 | Q10: =IF(AND(ISNUMBER(I10),ISNUMBER(M10),M10>0),I10/M10,"") | R10: =IF(AND(ISNUMBER(G10),ISNUMBER(H10),H10>0),G10/H10-1,"") -> 0.19317568 | S10: 0 | T10: =IF(ISNUMBER(S10),IF(S10>=1,1,0),"") -> 0 | U10: =IF(ISNUMBER(S10),IF(S10>=2,1,0),"") -> 0 | V10: 0 | W10: 1 | X10: B | Y10: https://www.sec.gov/Archives/edgar/data/1016125/000114036119005654/s002694x3_defm14a.htm | Z10: Company PR (Feb 4 2019): 'aggregate value of approximately $11 billion' (not labeled EV vs equity); no EV/equity value in proxy. Shares outstanding 31,680,263 at Mar 25 2019; no options outstanding. Ticker ULTI not shown in fetched 10-K text (cover lists Nasdaq only); verify. Closing 8-K: May 3 2019. 30-day VWAP dollar figure not stated. Debt is capital leases only.
A11: L09 | B11: Tableau Software, Inc. | C11: Salesforce.com, inc. | D11: 2019-06-10 | E11: strategic | F11: Application Software | G11: 177.88 | H11: 125.21 | I11: 15700 | J11: reported | K11: 1191.605 | M11: -91.547 | N11: =IF(AND(ISNUMBER(I11),ISNUMBER(K11),K11>0),I11/K11,"") -> 13.175507 | O11: =IF(AND(ISNUMBER(K11),ISNUMBER(L11),L11>0),K11/L11-1,"") | P11: =IF(AND(ISNUMBER(M11),ISNUMBER(K11),K11>0),M11/K11,"") -> -0.076826633 | Q11: =IF(AND(ISNUMBER(I11),ISNUMBER(M11),M11>0),I11/M11,"") | R11: =IF(AND(ISNUMBER(G11),ISNUMBER(H11),H11>0),G11/H11-1,"") -> 0.4206533 | S11: 1 | T11: =IF(ISNUMBER(S11),IF(S11>=1,1,0),"") -> 1 | U11: =IF(ISNUMBER(S11),IF(S11>=2,1,0),"") -> 0 | V11: 1 | W11: 1 | X11: B | Y11: https://www.sec.gov/Archives/edgar/data/1108524/000119312519188682/d82079ds4.htm | Z11: Fixed exchange ratio of 1.103 CRM shares per Tableau share (all stock). Offer price $177.88 is DERIVED (1.103 x $161.27) - no filing states an implied per-share price; this is the S-4's own inputs. EV $15.7bn 'net of cash' is company-stated (8-K Ex 99.1: https://www.sec.gov/Archives/edgar/data/1303652/000119312519168536/d763090dex991.htm); equity value not stated. Shares outstanding 6/24/2019: 77,003,759 Class A + 10,368,961 Class B = 87,372,720 (not fully diluted). June 7 is the last trading day before announcement; whether it is 'unaffected' (pre-leak) not verified. Closing 2019-08-01 per Salesforce 8-K.
A12: L12 | B12: Medidata Solutions, Inc. | C12: Dassault Systemes SE | D12: 2019-06-11 | E12: strategic | F12: Application Software | G12: 92.25 | I12: 5800 | J12: reported | K12: 660.002 | L12: 565.759 | M12: 80.734 | N12: =IF(AND(ISNUMBER(I12),ISNUMBER(K12),K12>0),I12/K12,"") -> 8.7878522 | O12: =IF(AND(ISNUMBER(K12),ISNUMBER(L12),L12>0),K12/L12-1,"") -> 0.166578 | P12: =IF(AND(ISNUMBER(M12),ISNUMBER(K12),K12>0),M12/K12,"") -> 0.12232387 | Q12: =IF(AND(ISNUMBER(I12),ISNUMBER(M12),M12>0),I12/M12,"") -> 71.84086 | R12: =IF(AND(ISNUMBER(G12),ISNUMBER(H12),H12>0),G12/H12-1,"") | S12: 1 | T12: =IF(ISNUMBER(S12),IF(S12>=1,1,0),"") -> 1 | U12: =IF(ISNUMBER(S12),IF(S12>=2,1,0),"") -> 0 | V12: 1 | W12: 0 | X12: B | Y12: https://www.sec.gov/Archives/edgar/data/1453814/000145381419000098/pressrelease.htm | Z12: EV $5.8bn is company-stated (8-K press release and Dassault release); equity value not stated. DEFM14A (https://www.sec.gov/Archives/edgar/data/1453814/000114036119013217/nc10003001x2_defm14a.htm) gives 62,449,313 shares outstanding at 7/19/2019 (basic). Closing 2019-10-28 per Medidata 8-K (Items 2.01, 1.02, 5.01, 3.01) filed 10/28/2019. Acquirer is French (Dassault Systemes SE); target is US-listed (NASDAQ) and US-based. Only the first ~140k characters of the DEFM14A were read; premium may exist in later fairness-opinion sections. Ticker MDSO per DEFM14A text.
A13: L10 | B13: Carbonite, Inc. | C13: Open Text Corporation | D13: 2019-11-11 | E13: strategic | F13: Infrastructure Software | G13: 23 | H13: 12.93 | I13: 1420 | J13: reported | K13: 405.287 | L13: 281.134 | M13: 58.256 | N13: =IF(AND(ISNUMBER(I13),ISNUMBER(K13),K13>0),I13/K13,"") -> 3.50369 | O13: =IF(AND(ISNUMBER(K13),ISNUMBER(L13),L13>0),K13/L13-1,"") -> 0.44161503 | P13: =IF(AND(ISNUMBER(M13),ISNUMBER(K13),K13>0),M13/K13,"") -> 0.14374012 | Q13: =IF(AND(ISNUMBER(I13),ISNUMBER(M13),M13>0),I13/M13,"") -> 24.375172 | R13: =IF(AND(ISNUMBER(G13),ISNUMBER(H13),H13>0),G13/H13-1,"") -> 0.77880897 | S13: 0 | T13: =IF(ISNUMBER(S13),IF(S13>=1,1,0),"") -> 0 | U13: =IF(ISNUMBER(S13),IF(S13>=2,1,0),"") -> 0 | V13: 1 | W13: 1 | X13: B | Y13: https://www.sec.gov/Archives/edgar/data/1340127/000119312519289310/d832010dex991.htm | Z13: EV approx $1.42bn is company-stated (press release); equity value not stated. CONFLICT: press release gives unaffected date as Sept 5, 2019; SC 14D-9 (https://www.sec.gov/Archives/edgar/data/1340127/000119312519299069/d839795dsc14d9.htm) defines unaffected price as the price before the Sept 7 article ($12.93); 23.00/12.93 = 1.779 consistent with 78%. 35,042,212 shares outstanding 11/21/2019 (basic). Tender offer; merger completed 2019-12-24 per SC 14D-9/A (https://www.sec.gov/Archives/edgar/data/1340127/000119312519322988/d717414dsc14d9a.htm). Acquirer OpenText is Canada-based (country from general knowledge, not a filing in this pass). Ticker CARB from 10-Q XBRL cover.
A14: L11 | B14: Instructure, Inc. | C14: Thoma Bravo | D14: 2019-12-04 | E14: sponsor | F14: Application Software | G14: 47.6 | I14: 1872.795 | J14: calculated_from_bridge | K14: 245.529 | L14: 198.048 | M14: -53.386 | N14: =IF(AND(ISNUMBER(I14),ISNUMBER(K14),K14>0),I14/K14,"") -> 7.6275919 | O14: =IF(AND(ISNUMBER(K14),ISNUMBER(L14),L14>0),K14/L14-1,"") -> 0.23974491 | P14: =IF(AND(ISNUMBER(M14),ISNUMBER(K14),K14>0),M14/K14,"") -> -0.21743256 | Q14: =IF(AND(ISNUMBER(I14),ISNUMBER(M14),M14>0),I14/M14,"") | R14: =IF(AND(ISNUMBER(G14),ISNUMBER(H14),H14>0),G14/H14-1,"") | S14: 0 | T14: =IF(ISNUMBER(S14),IF(S14>=1,1,0),"") -> 0 | U14: =IF(ISNUMBER(S14),IF(S14>=2,1,0),"") -> 0 | V14: 1 | W14: 0 | X14: A | Y14: https://www.sec.gov/Archives/edgar/data/1355754/000119312519305817/d816713dex991.htm | Z14: Equity value approx $2.0bn is company-stated (8-K Ex 99.1: 'aggregate equity value of approximately $2.0 billion'); no EV stated. DEFM14A (https://www.sec.gov/Archives/edgar/data/1355754/000119312520000113/d812272ddefm14a.htm): 38,257,326 shares outstanding at 1/1/2020; background cites bidder-assumed fully diluted count of approx 37.67 million (Jan 2019, not a company dil figure). Unaffected date/price not found in retrievable portions of proxy. Closing 2020-03-24 inferred from 8-K filings with report date 3/24/2020 in EDGAR submissions index (form type not displayed); verify. Ticker INST from 10-Q XBRL cover.
A15: L14 | B15: Slack Technologies, Inc. | C15: Salesforce, Inc. | D15: 2020-12-01 | E15: strategic | F15: Application Software | G15: 47.03 | I15: 27700 | J15: reported | K15: 768.142 | L15: 507.409 | M15: -302.864 | N15: =IF(AND(ISNUMBER(I15),ISNUMBER(K15),K15>0),I15/K15,"") -> 36.061041 | O15: =IF(AND(ISNUMBER(K15),ISNUMBER(L15),L15>0),K15/L15-1,"") -> 0.51385174 | P15: =IF(AND(ISNUMBER(M15),ISNUMBER(K15),K15>0),M15/K15,"") -> -0.39428127 | Q15: =IF(AND(ISNUMBER(I15),ISNUMBER(M15),M15>0),I15/M15,"") | R15: =IF(AND(ISNUMBER(G15),ISNUMBER(H15),H15>0),G15/H15-1,"") | S15: 0 | T15: =IF(ISNUMBER(S15),IF(S15>=1,1,0),"") -> 0 | U15: =IF(ISNUMBER(S15),IF(S15>=2,1,0),"") -> 0 | V15: 1 | W15: 0 | X15: B | Y15: https://www.sec.gov/Archives/edgar/data/1108524/000119312520307395/d86936dex991.htm | Z15: Consideration $26.79 cash + 0.0776 CRM share per Slack share; 'offer' 47.03 is proxy's value at Nov 24 2020 CRM close (value moves with CRM price; EV $27.7B PR based on Nov 30 CRM close). No premium or Slack unaffected closing price found in filings read. Basic shares 501,490,143 Class A + 79,094,868 Class B (Jan 25 2021). Closing: Salesforce 8-K Jul 21 2021. Equity value not stated.
A16: L46 | B16: RealPage | C16: Thoma Bravo | D16: 2020-12-21 | E16: sponsor | F16: Application Software | G16: 88.75 | H16: 67.83 | I16: 10200 | J16: reported | K16: 1115.196 | L16: 960.343 | M16: 230.382 | N16: =IF(AND(ISNUMBER(I16),ISNUMBER(K16),K16>0),I16/K16,"") -> 9.1463743 | O16: =IF(AND(ISNUMBER(K16),ISNUMBER(L16),L16>0),K16/L16-1,"") -> 0.1612476 | P16: =IF(AND(ISNUMBER(M16),ISNUMBER(K16),K16>0),M16/K16,"") -> 0.20658431 | Q16: =IF(AND(ISNUMBER(I16),ISNUMBER(M16),M16>0),I16/M16,"") -> 44.274292 | R16: =IF(AND(ISNUMBER(G16),ISNUMBER(H16),H16>0),G16/H16-1,"") -> 0.3084181 | S16: 0 | T16: =IF(ISNUMBER(S16),IF(S16>=1,1,0),"") -> 0 | U16: =IF(ISNUMBER(S16),IF(S16>=2,1,0),"") -> 0 | V16: 1 | W16: 1 | X16: B | Y16: https://www.sec.gov/Archives/edgar/data/1286225/000119312520322436/d24232dex992.htm ; https://www.sec.gov/Archives/edgar/data/1286225/000119312521029970/d52613ddefm14a.htm ; https://www.sec.gov/Archives/edgar/data/1286225/000119312521125818/d177605d8k.htm | Z16: Press release: 'values RealPage at approximately $10.2 billion, including net debt' (company-stated EV-type figure; no separate equity value). Merger agreement dated 2020-12-20; announced 2020-12-21. DEFM14A text read did not include premium/VWAP/diluted count (102,060,098 basic shares at record date). Closing 8-K states ~$11.8B total merger consideration incl. $6.88B equity (as reported by tool extract; not used for head). Closing 2021-04-22 per 8-K Item 2.01.
A17: L15 | B17: Talend S.A. | C17: Thoma Bravo | D17: 2021-03-10 | E17: sponsor | F17: Infrastructure Software | G17: 66 | H17: 51.3 | I17: 2400 | J17: reported | K17: 287.471 | L17: 247.861 | M17: -62.371 | N17: =IF(AND(ISNUMBER(I17),ISNUMBER(K17),K17>0),I17/K17,"") -> 8.3486682 | O17: =IF(AND(ISNUMBER(K17),ISNUMBER(L17),L17>0),K17/L17-1,"") -> 0.15980731 | P17: =IF(AND(ISNUMBER(M17),ISNUMBER(K17),K17>0),M17/K17,"") -> -0.21696449 | Q17: =IF(AND(ISNUMBER(I17),ISNUMBER(M17),M17>0),I17/M17,"") | R17: =IF(AND(ISNUMBER(G17),ISNUMBER(H17),H17>0),G17/H17-1,"") -> 0.28654971 | S17: 1 | T17: =IF(ISNUMBER(S17),IF(S17>=1,1,0),"") -> 1 | U17: =IF(ISNUMBER(S17),IF(S17>=2,1,0),"") -> 0 | V17: 1 | W17: 1 | X17: B | Y17: https://www.thomabravo.com/press-releases/talend-to-be-acquired-by-thoma-bravo-in-a-2.4-billion-transaction | Z17: Talend S.A. is French-incorporated (ADSs on Nasdaq) but US-based (Redwood City) and a US domestic 10-K filer, so treated as in scope. $2.4B 'including net debt' = company-stated EV. Tender offer completed ~Jul 29 2021 (initial period) and subsequent offer period ended Aug 9 2021; Thoma Bravo announced completion Sep 2 2021 (used as close). 30-day VWAP not found for the final offer. Basic shares 32,709,507 (Jun 9 2021).
A18: P02 | B18: Nuance Communications | C18: Microsoft | D18: 2021-04-12 | E18: strategic | F18: Application Software | G18: 56 | H18: 45.58 | I18: 19700 | J18: reported | K18: 1463.1 | L18: 1519.829 | M18: 223.852 | N18: =IF(AND(ISNUMBER(I18),ISNUMBER(K18),K18>0),I18/K18,"") -> 13.464562 | O18: =IF(AND(ISNUMBER(K18),ISNUMBER(L18),L18>0),K18/L18-1,"") -> -0.03732591 | P18: =IF(AND(ISNUMBER(M18),ISNUMBER(K18),K18>0),M18/K18,"") -> 0.15299843 | Q18: =IF(AND(ISNUMBER(I18),ISNUMBER(M18),M18>0),I18/M18,"") -> 88.004574 | R18: =IF(AND(ISNUMBER(G18),ISNUMBER(H18),H18>0),G18/H18-1,"") -> 0.22860904 | S18: 2 | T18: =IF(ISNUMBER(S18),IF(S18>=1,1,0),"") -> 1 | U18: =IF(ISNUMBER(S18),IF(S18>=2,1,0),"") -> 1 | V18: 1 | W18: 1 | X18: B | Y18: https://www.sec.gov/Archives/edgar/data/1002517/000119312521112515/d22854dex991.htm | Z18: EV $19.7bn stated by the company 'inclusive of net debt'; equity value not stated. Close date from secondary press (Windows Central).
A19: L16 | B19: Proofpoint, Inc. | C19: Thoma Bravo | D19: 2021-04-26 | E19: sponsor | F19: Cybersecurity | G19: 176 | J19: undisclosed | K19: 1050.01 | L19: 888.19 | M19: 0.769 | N19: =IF(AND(ISNUMBER(I19),ISNUMBER(K19),K19>0),I19/K19,"") | O19: =IF(AND(ISNUMBER(K19),ISNUMBER(L19),L19>0),K19/L19-1,"") -> 0.18219075 | P19: =IF(AND(ISNUMBER(M19),ISNUMBER(K19),K19>0),M19/K19,"") -> 0.00073237398 | Q19: =IF(AND(ISNUMBER(I19),ISNUMBER(M19),M19>0),I19/M19,"") | R19: =IF(AND(ISNUMBER(G19),ISNUMBER(H19),H19>0),G19/H19-1,"") | S19: 1 | T19: =IF(ISNUMBER(S19),IF(S19>=1,1,0),"") -> 1 | U19: =IF(ISNUMBER(S19),IF(S19>=2,1,0),"") -> 0 | V19: 0 | W19: 0 | X19: A | Y19: https://www.proofpoint.com/us/newsroom/press-releases/proofpoint-enters-definitive-agreement-be-acquired-thoma-bravo-123-billion | Z19: '$12.3 billion' per PR 'values Proofpoint at approximately'; EV vs equity not specified. dil = FY2020 diluted weighted avg shares (57,324K), not a deal fully diluted count. 57,627,801 shares outstanding Jun 3 2021. Completion Aug 31 2021 per company PR. D&A from cash flow, EBITDA is GAAP and ~0 due to large amortization.
A20: L17 | B20: Cloudera, Inc. | C20: KKR + Clayton, Dubilier & Rice | D20: 2021-06-01 | E20: sponsor | F20: Infrastructure Software | G20: 16 | J20: undisclosed | K20: 883.081 | L20: 817.183 | M20: -47.762 | N20: =IF(AND(ISNUMBER(I20),ISNUMBER(K20),K20>0),I20/K20,"") | O20: =IF(AND(ISNUMBER(K20),ISNUMBER(L20),L20>0),K20/L20-1,"") -> 0.080640444 | P20: =IF(AND(ISNUMBER(M20),ISNUMBER(K20),K20>0),M20/K20,"") -> -0.054085639 | Q20: =IF(AND(ISNUMBER(I20),ISNUMBER(M20),M20>0),I20/M20,"") | R20: =IF(AND(ISNUMBER(G20),ISNUMBER(H20),H20>0),G20/H20-1,"") | S20: 0 | T20: =IF(ISNUMBER(S20),IF(S20>=1,1,0),"") -> 0 | U20: =IF(ISNUMBER(S20),IF(S20>=2,1,0),"") -> 0 | V20: 0 | W20: 0 | X20: B | Y20: https://www.sec.gov/Archives/edgar/data/1535379/000119312521177699/d168575dex991.htm | Z20: Announcement date Jun 1 2021 per 8-K ex 99.1. '$5.3 billion' = 'all cash transaction valued at approximately'; proxy calls it total funds needed, not EV. 296,132,583 shares outstanding at Jul 1 2021. Item 1 description is generic; the 10-K goes on to describe the platform. Close Oct 8 2021 per 8-K.
A21: L45 | B21: Cornerstone OnDemand | C21: Clearlake Capital | D21: 2021-08-05 | E21: sponsor | F21: Application Software | G21: 57.5 | I21: 5200 | J21: reported | K21: 800.053 | M21: 122.061 | N21: =IF(AND(ISNUMBER(I21),ISNUMBER(K21),K21>0),I21/K21,"") -> 6.4995694 | O21: =IF(AND(ISNUMBER(K21),ISNUMBER(L21),L21>0),K21/L21-1,"") | P21: =IF(AND(ISNUMBER(M21),ISNUMBER(K21),K21>0),M21/K21,"") -> 0.15256614 | Q21: =IF(AND(ISNUMBER(I21),ISNUMBER(M21),M21>0),I21/M21,"") -> 42.60165 | R21: =IF(AND(ISNUMBER(G21),ISNUMBER(H21),H21>0),G21/H21-1,"") | S21: 0 | T21: =IF(ISNUMBER(S21),IF(S21>=1,1,0),"") -> 0 | U21: =IF(ISNUMBER(S21),IF(S21>=2,1,0),"") -> 0 | V21: 1 | W21: 0 | X21: B | Y21: https://www.sec.gov/Archives/edgar/data/1401680/000119312521238137/d135195dex991.htm ; https://www.sec.gov/Archives/edgar/data/1401680/000114036121030923/ny20000316x2_defm14a.htm ; https://www.sec.gov/Archives/edgar/data/1401680/000119312521302087/d247133dsc13da.htm | Z21: Offer is $57.50 per share cash (not $58). Press release: 'enterprise value of approximately $5.2 billion'; no equity value stated; DEFM14A cites ~$5.3B total funding (not EV). No fully diluted share count found (66,857,760 basic at 2021-08-24 record date). un_px null because June 1 2021 close not stated in text read; DEFM14A text was truncated by tool so fairness-opinion sections may contain it. Closing date 2021-10-15 from Clearlake Schedule 13D/A (date of event) - closing 8-K not located. Ticker/exchange from filing naming/memory of listing (CSOD, Nasdaq) not independently quoted.
A22: L19 | B22: Citrix Systems | C22: Vista Equity Partners + Elliott (Evergreen Coast Capital) / Cloud Software Group | D22: 2022-01-31 | E22: sponsor | F22: Infrastructure Software | G22: 104 | I22: 16500 | J22: reported | K22: 3175.978 | L22: 3236.867 | N22: =IF(AND(ISNUMBER(I22),ISNUMBER(K22),K22>0),I22/K22,"") -> 5.1952501 | O22: =IF(AND(ISNUMBER(K22),ISNUMBER(L22),L22>0),K22/L22-1,"") -> -0.018811091 | P22: =IF(AND(ISNUMBER(M22),ISNUMBER(K22),K22>0),M22/K22,"") | Q22: =IF(AND(ISNUMBER(I22),ISNUMBER(M22),M22>0),I22/M22,"") | R22: =IF(AND(ISNUMBER(G22),ISNUMBER(H22),H22>0),G22/H22-1,"") | S22: 0 | T22: =IF(ISNUMBER(S22),IF(S22>=1,1,0),"") -> 0 | U22: =IF(ISNUMBER(S22),IF(S22>=2,1,0),"") -> 0 | V22: 1 | W22: 0 | X22: B | Y22: https://www.sec.gov/Archives/edgar/data/877890/000119312522023669/d293942ddefa14a.htm | Z22: Press release/DEFA14A: 'The transaction is valued at $16.5 billion in cash'; Goodwin repost of release: 'all-cash transaction valued at $16.5 billion, including the assumption of Citrix debt' - so treated as company-stated enterprise value (evq B). Equity value and diluted shares not stated in documents read (DEFM14A: 125,913,152 basic shares at 2022-03-08 record date; total funding approx $17.3 billion). No single-day unaffected closing price stated; unaffected metric is a 5-day VWAP as of 2021-12-07, so un_px null. Q4/FY2021 results (revenue $851M / $3.22B) were released on announcement day 2022-01-31 but the last filed 10-Q was Q3 2021, which was used per brief. Close date 2022-09-30 from Goodwin/vmblog completion-release dates; a Business Wire URL date code suggests 2022-09-29, so +/-1 day uncertain. Buyer is a consortium (Vista + Elliott affiliates Evergreen Coast); Nasdaq press-release page could not be fetched (HTTP 429). rev_prior not built.
A23: L41 | B23: Mandiant | C23: Google | D23: 2022-03-08 | E23: strategic | F23: Cybersecurity | G23: 23 | J23: undisclosed | K23: 483.455 | L23: 399.709 | M23: -264.748 | N23: =IF(AND(ISNUMBER(I23),ISNUMBER(K23),K23>0),I23/K23,"") | O23: =IF(AND(ISNUMBER(K23),ISNUMBER(L23),L23>0),K23/L23-1,"") -> 0.20951742 | P23: =IF(AND(ISNUMBER(M23),ISNUMBER(K23),K23>0),M23/K23,"") -> -0.54761663 | Q23: =IF(AND(ISNUMBER(I23),ISNUMBER(M23),M23>0),I23/M23,"") | R23: =IF(AND(ISNUMBER(G23),ISNUMBER(H23),H23>0),G23/H23-1,"") | S23: 0 | T23: =IF(ISNUMBER(S23),IF(S23>=1,1,0),"") -> 0 | U23: =IF(ISNUMBER(S23),IF(S23>=2,1,0),"") -> 0 | V23: 0 | W23: 0 | X23: C | Y23: https://www.sec.gov/Archives/edgar/data/1370880/000110465922031786/tm228582d1_ex99-1.htm | Z23: Release: "valued at approximately $5.4 billion, inclusive of Mandiant's net cash" - not labeled equity or EV, so htype=consideration; ev not stated in the filing read. Unaffected date Feb 7, 2022 (last full trading day before sale-speculation reports); its dollar price not stated in material read. Premium to closing price 53%, to 10-day VWAP 57%. Cash-flow D&A includes discontinued ops; adjusted as shown. Close date Sept 12, 2022 per Google completion announcement (search listing, not fetched).
A24: P03 | B24: Anaplan Inc. | C24: Thoma Bravo | D24: 2022-03-20 | E24: sponsor | F24: Application Software | G24: 63.75 | H24: 50.59 | I24: 10100.629 | J24: calculated_from_bridge | K24: 592.176 | L24: 447.8 | M24: -172.199 | N24: =IF(AND(ISNUMBER(I24),ISNUMBER(K24),K24>0),I24/K24,"") -> 17.056802 | O24: =IF(AND(ISNUMBER(K24),ISNUMBER(L24),L24>0),K24/L24-1,"") -> 0.32241179 | P24: =IF(AND(ISNUMBER(M24),ISNUMBER(K24),K24>0),M24/K24,"") -> -0.29079024 | Q24: =IF(AND(ISNUMBER(I24),ISNUMBER(M24),M24>0),I24/M24,"") | R24: =IF(AND(ISNUMBER(G24),ISNUMBER(H24),H24>0),G24/H24-1,"") -> 0.26013046 | S24: 0 | T24: =IF(ISNUMBER(S24),IF(S24>=1,1,0),"") -> 0 | U24: =IF(ISNUMBER(S24),IF(S24>=2,1,0),"") -> 0 | V24: 1 | W24: 1 | X24: C | Y24: https://www.thomabravo.com/press-releases/thoma-bravo-completes-acquisition-of-anaplan | Z24: Price cut from $66.00 to $63.75 on 2022-06-06; final terms used. Value sources conflict ($10.4bn Thoma Bravo vs $9.6bn Techzine). Debt 0 inferred from absence of debt line items.
A25: L18 | B25: SailPoint Technologies Holdings, Inc. | C25: Thoma Bravo | D25: 2022-04-11 | E25: sponsor | F25: Cybersecurity | G25: 65.25 | J25: undisclosed | K25: 438.954 | L25: 365.254 | M25: -36.7 | N25: =IF(AND(ISNUMBER(I25),ISNUMBER(K25),K25>0),I25/K25,"") | O25: =IF(AND(ISNUMBER(K25),ISNUMBER(L25),L25>0),K25/L25-1,"") -> 0.20177739 | P25: =IF(AND(ISNUMBER(M25),ISNUMBER(K25),K25>0),M25/K25,"") -> -0.08360785 | Q25: =IF(AND(ISNUMBER(I25),ISNUMBER(M25),M25>0),I25/M25,"") | R25: =IF(AND(ISNUMBER(G25),ISNUMBER(H25),H25>0),G25/H25-1,"") | S25: 0 | T25: =IF(ISNUMBER(S25),IF(S25>=1,1,0),"") -> 0 | U25: =IF(ISNUMBER(S25),IF(S25>=2,1,0),"") -> 0 | V25: 0 | W25: 0 | X25: A | Y25: https://www.sec.gov/Archives/edgar/data/1627857/000119312522100936/d248941dex991.htm | Z25: '$6.9 billion' per PR 'values SailPoint at approximately'; EV vs equity not specified. Proxy: total funds needed approx $7.5B; 94,339,273 shares outstanding at record date. Diluted weighted shares 92,664K (FY2021) not used as dil. Close Aug 16 2022 per Thoma Bravo PR.
A26: L20 | B26: Zendesk | C26: Hellman & Friedman + Permira consortium | D26: 2022-06-24 | E26: sponsor | F26: Application Software | G26: 77.5 | J26: undisclosed | K26: 1428.882 | M26: -151.618 | N26: =IF(AND(ISNUMBER(I26),ISNUMBER(K26),K26>0),I26/K26,"") | O26: =IF(AND(ISNUMBER(K26),ISNUMBER(L26),L26>0),K26/L26-1,"") | P26: =IF(AND(ISNUMBER(M26),ISNUMBER(K26),K26>0),M26/K26,"") -> -0.10610953 | Q26: =IF(AND(ISNUMBER(I26),ISNUMBER(M26),M26>0),I26/M26,"") | R26: =IF(AND(ISNUMBER(G26),ISNUMBER(H26),H26>0),G26/H26-1,"") | S26: 0 | T26: =IF(ISNUMBER(S26),IF(S26>=1,1,0),"") -> 0 | U26: =IF(ISNUMBER(S26),IF(S26>=2,1,0),"") -> 0 | V26: 0 | W26: 0 | X26: C | Y26: https://www.businesswire.com/news/home/20220624005233/en/Zendesk-to-Be-Acquired-by-Investor-Group-Led-by-Hellman-Friedman-and-Permira-for-%2410.2-Billion | Z26: Release says deal 'values Zendesk at approximately $10.2 billion' without stating equity vs enterprise, so htype=consideration and eq/ev null. DEFM14A shows total funds needed approx $10.47 billion (financing, not valuation); 123,465,884 shares outstanding at 2022-08-04 record date; no diluted count or unaffected price stated. Press release anchors premium on 2022-06-23 close while DEFA14A calls it 'unaffected share price'; any earlier leak-affected date was not found in sources read. Buyer is a consortium led by H&F (US) and Permira (UK); bc set US for H&F. Close date 2022-11-22 from Zendesk completion release.
A27: L23 | B27: Ping Identity | C27: Thoma Bravo | D27: 2022-08-03 | E27: sponsor | F27: Cybersecurity | G27: 28.5 | I27: 2800 | J27: reported | K27: 308.319 | L27: 271.044 | M27: -52.956 | N27: =IF(AND(ISNUMBER(I27),ISNUMBER(K27),K27>0),I27/K27,"") -> 9.0815032 | O27: =IF(AND(ISNUMBER(K27),ISNUMBER(L27),L27>0),K27/L27-1,"") -> 0.1375238 | P27: =IF(AND(ISNUMBER(M27),ISNUMBER(K27),K27>0),M27/K27,"") -> -0.17175717 | Q27: =IF(AND(ISNUMBER(I27),ISNUMBER(M27),M27>0),I27/M27,"") | R27: =IF(AND(ISNUMBER(G27),ISNUMBER(H27),H27>0),G27/H27-1,"") | S27: 0 | T27: =IF(ISNUMBER(S27),IF(S27>=1,1,0),"") -> 0 | U27: =IF(ISNUMBER(S27),IF(S27>=2,1,0),"") -> 0 | V27: 1 | W27: 0 | X27: B | Y27: https://www.sec.gov/Archives/edgar/data/1679826/000110465922085439/tm2222402d1_ex99-1.htm | Z27: Release: 'valued at an Enterprise Value of approximately $2.8 billion' (no equity value). DEFM14A: 86,281,946 shares outstanding at 2022-09-12 record date; funds needed approx $2.8 billion; no dollar close for 2022-08-02 stated in sources read (Aug 2 is last full trading day before announcement, not necessarily clean of leaks). Close date from Ping/Thoma Bravo completion release. Description is the one verbatim mission sentence retrieved from Item 1. rev_prior not built.
A28: L22 | B28: Avalara | C28: Vista Equity Partners | D28: 2022-08-08 | E28: sponsor | F28: Application Software | G28: 93.5 | I28: 8400 | J28: reported | K28: 789.432 | L28: 595.307 | M28: -98.746 | N28: =IF(AND(ISNUMBER(I28),ISNUMBER(K28),K28>0),I28/K28,"") -> 10.640562 | O28: =IF(AND(ISNUMBER(K28),ISNUMBER(L28),L28>0),K28/L28-1,"") -> 0.32609225 | P28: =IF(AND(ISNUMBER(M28),ISNUMBER(K28),K28>0),M28/K28,"") -> -0.12508487 | Q28: =IF(AND(ISNUMBER(I28),ISNUMBER(M28),M28>0),I28/M28,"") | R28: =IF(AND(ISNUMBER(G28),ISNUMBER(H28),H28>0),G28/H28-1,"") | S28: 0 | T28: =IF(ISNUMBER(S28),IF(S28>=1,1,0),"") -> 0 | U28: =IF(ISNUMBER(S28),IF(S28>=2,1,0),"") -> 0 | V28: 1 | W28: 0 | X28: B | Y28: https://www.vistaequitypartners.com/news/avalara-to-be-acquired-by-vista-equity-partners-for-8-4-billion/ | Z28: Release: 'all-cash transaction valued at $8.4 billion, inclusive of Avalara's net debt' - treated as company-stated EV (evq B); equity value not stated. Offer price is $93.50 (not $93). DEFM14A: 88,557,882 shares outstanding at 2022-09-08 record date; no July 6 dollar close stated. Q2 2022 10-Q filing date not confirmed to precede announcement (cover date 2022-08-03, filed on or just before 2022-08-08). Close date 2022-10-19 from Business Wire/SEC 8-K release. rev_prior not built.
A29: L21 | B29: Coupa Software | C29: Thoma Bravo | D29: 2022-12-12 | E29: sponsor | F29: Application Software | G29: 81 | I29: 8000 | J29: reported | K29: 818.108 | L29: 695.535 | M29: -128.224 | N29: =IF(AND(ISNUMBER(I29),ISNUMBER(K29),K29>0),I29/K29,"") -> 9.77866 | O29: =IF(AND(ISNUMBER(K29),ISNUMBER(L29),L29>0),K29/L29-1,"") -> 0.17622837 | P29: =IF(AND(ISNUMBER(M29),ISNUMBER(K29),K29>0),M29/K29,"") -> -0.15673236 | Q29: =IF(AND(ISNUMBER(I29),ISNUMBER(M29),M29>0),I29/M29,"") | R29: =IF(AND(ISNUMBER(G29),ISNUMBER(H29),H29>0),G29/H29-1,"") | S29: 0 | T29: =IF(ISNUMBER(S29),IF(S29>=1,1,0),"") -> 0 | U29: =IF(ISNUMBER(S29),IF(S29>=2,1,0),"") -> 0 | V29: 1 | W29: 0 | X29: B | Y29: https://www.sec.gov/Archives/edgar/data/1385867/000119312522302253/d400208dex991.htm | Z29: Release states 'an enterprise value of $8.0 billion' (no equity value stated). DEFM14A: 75,541,300 shares outstanding at 2023-01-19; total funds needed approx $8.3 billion (financing); no dollar unaffected price in documents read; 30-day VWAP premium given but not the VWAP price. Close date from Coupa completion release dated 2023-02-28. rev_prior not built.
A30: L25 | B30: Duck Creek Technologies, Inc. | C30: Vista Equity Partners | D30: 2023-01-09 | E30: sponsor | F30: Application Software | G30: 19 | H30: 12.99 | J30: undisclosed | K30: 310.082 | L30: 274.865 | M30: 8.174 | N30: =IF(AND(ISNUMBER(I30),ISNUMBER(K30),K30>0),I30/K30,"") | O30: =IF(AND(ISNUMBER(K30),ISNUMBER(L30),L30>0),K30/L30-1,"") -> 0.12812472 | P30: =IF(AND(ISNUMBER(M30),ISNUMBER(K30),K30>0),M30/K30,"") -> 0.026360769 | Q30: =IF(AND(ISNUMBER(I30),ISNUMBER(M30),M30>0),I30/M30,"") | R30: =IF(AND(ISNUMBER(G30),ISNUMBER(H30),H30>0),G30/H30-1,"") -> 0.46266359 | S30: 0 | T30: =IF(ISNUMBER(S30),IF(S30>=1,1,0),"") -> 0 | U30: =IF(ISNUMBER(S30),IF(S30>=2,1,0),"") -> 0 | V30: 0 | W30: 1 | X30: A | Y30: https://www.sec.gov/Archives/edgar/data/1160951/000119312523004161/d442317dex991.htm | Z30: Press release states 'all-cash transaction valued at approximately $2.6 billion' without labeling equity or EV; no aggregate equity value or EV stated in release or DEFM14A (DEFM14A: Vista equity commitment up to ~$2.65bn; 136,906,439 shares outstanding at record date). 30-day VWAP premium 64% stated but dollar VWAP not stated. Nov 30, 2022 10-Q filed same day as announcement (2023-01-09). Closing date from Duck Creek press release dated 2023-03-30. Description: second sentence of Item 1 overview ('Core systems comprise the end-to-end back-office infrastructure of insurance companies...') omitted because fetch returned it in fragments. DEFM14A: https://www.sec.gov/Archives/edgar/data/1160951/000114036123009051/ny20006914x5_defm14a.htm
A31: L42 | B31: Sumo Logic | C31: Francisco Partners | D31: 2023-02-09 | E31: sponsor | F31: Infrastructure Software | G31: 12.05 | I31: 1377.856 | J31: calculated_from_bridge | K31: 287.964 | L31: 229.228 | M31: -112.334 | N31: =IF(AND(ISNUMBER(I31),ISNUMBER(K31),K31>0),I31/K31,"") -> 4.7848203 | O31: =IF(AND(ISNUMBER(K31),ISNUMBER(L31),L31>0),K31/L31-1,"") -> 0.25623397 | P31: =IF(AND(ISNUMBER(M31),ISNUMBER(K31),K31>0),M31/K31,"") -> -0.39009737 | Q31: =IF(AND(ISNUMBER(I31),ISNUMBER(M31),M31>0),I31/M31,"") | R31: =IF(AND(ISNUMBER(G31),ISNUMBER(H31),H31>0),G31/H31-1,"") | S31: 1 | T31: =IF(ISNUMBER(S31),IF(S31>=1,1,0),"") -> 1 | U31: =IF(ISNUMBER(S31),IF(S31>=2,1,0),"") -> 0 | V31: 1 | W31: 0 | X31: C | Y31: https://www.sec.gov/Archives/edgar/data/1643269/000119312523029399/d392451dex991.htm | Z31: Release: "aggregate equity valuation of approximately $1.7 billion"; ev not stated. Unaffected dollar price and VWAP not found in release or DEFM14A portion read. DEFM14A: 124,088,187 shares outstanding at Apr 3, 2023 record date. Sector classification (Infrastructure Software vs Cybersecurity) is a judgment call. Close date May 12, 2023 per completion announcement (search listing).
A32: P08 | B32: Qualtrics International | C32: Silver Lake / CPP Investments | D32: 2023-03-13 | E32: sponsor | F32: Application Software | G32: 18.15 | H32: 11.21 | I32: 11680.1 | J32: calculated_from_bridge | K32: 1458.6 | L32: 1075.7 | M32: -951.435 | N32: =IF(AND(ISNUMBER(I32),ISNUMBER(K32),K32>0),I32/K32,"") -> 8.0077472 | O32: =IF(AND(ISNUMBER(K32),ISNUMBER(L32),L32>0),K32/L32-1,"") -> 0.35595426 | P32: =IF(AND(ISNUMBER(M32),ISNUMBER(K32),K32>0),M32/K32,"") -> -0.65229329 | Q32: =IF(AND(ISNUMBER(I32),ISNUMBER(M32),M32>0),I32/M32,"") | R32: =IF(AND(ISNUMBER(G32),ISNUMBER(H32),H32>0),G32/H32-1,"") -> 0.6190901 | S32: 0 | T32: =IF(ISNUMBER(S32),IF(S32>=1,1,0),"") -> 0 | U32: =IF(ISNUMBER(S32),IF(S32>=2,1,0),"") -> 0 | V32: 1 | W32: 1 | X32: C | Y32: https://www.sec.gov/Archives/edgar/data/1747748/000162828023007614/exhibit991-pressrelease1.htm | Z32: Headline $12.5bn (press release) vs $12.4bn stated as equity value in an 8-K (summarised text); equity set to 12.4bn; treated as equity. Sources differ by one day on announcement (03-12 signing, 03-13 public). SAP was majority holder (DEFM14C). Debt 0 inferred.
A33: L24 | B33: Momentive Global | C33: Symphony Technology Group (STG) | D33: 2023-03-13 | E33: sponsor | F33: Application Software | G33: 9.46 | J33: undisclosed | K33: 480.917 | L33: 443.786 | M33: -52.612 | N33: =IF(AND(ISNUMBER(I33),ISNUMBER(K33),K33>0),I33/K33,"") | O33: =IF(AND(ISNUMBER(K33),ISNUMBER(L33),L33>0),K33/L33-1,"") -> 0.083668705 | P33: =IF(AND(ISNUMBER(M33),ISNUMBER(K33),K33>0),M33/K33,"") -> -0.10939934 | Q33: =IF(AND(ISNUMBER(I33),ISNUMBER(M33),M33>0),I33/M33,"") | R33: =IF(AND(ISNUMBER(G33),ISNUMBER(H33),H33>0),G33/H33-1,"") | S33: 1 | T33: =IF(ISNUMBER(S33),IF(S33>=1,1,0),"") -> 1 | U33: =IF(ISNUMBER(S33),IF(S33>=2,1,0),"") -> 0 | V33: 0 | W33: 0 | X33: C | Y33: https://www.surveymonkey.com/mp/news/stg-to-acquire-momentive/ | Z33: DATE FLAG: assignment listed announced year 2022 but announcement was 2023-03-13 (agreement with STG consortium; strategic review followed Oct 2022 rumors). Release says 'values Momentive at approximately $1.5 billion' without equity/EV label, so htype=consideration. Unaffected reference is 'the day prior to media rumors' re Oct 19, 2022; exact date and dollar price not stated in sources read, so un_date/un_px null. DEFM14A: 150,689,947 shares outstanding and entitled to vote; no diluted count. Close date 2023-05-31 per completion exhibit (Business Wire URL code suggests 2023-05-30 release date; +/-1 day uncertain).
A34: L26 | B34: New Relic, Inc. | C34: Francisco Partners and TPG | D34: 2023-07-31 | E34: sponsor | F34: Infrastructure Software | G34: 87 | I34: 6120.232 | J34: calculated_from_bridge | K34: 925.626 | L34: 785.521 | M34: -121.863 | N34: =IF(AND(ISNUMBER(I34),ISNUMBER(K34),K34>0),I34/K34,"") -> 6.6119923 | O34: =IF(AND(ISNUMBER(K34),ISNUMBER(L34),L34>0),K34/L34-1,"") -> 0.17835933 | P34: =IF(AND(ISNUMBER(M34),ISNUMBER(K34),K34>0),M34/K34,"") -> -0.13165469 | Q34: =IF(AND(ISNUMBER(I34),ISNUMBER(M34),M34>0),I34/M34,"") | R34: =IF(AND(ISNUMBER(G34),ISNUMBER(H34),H34>0),G34/H34-1,"") | S34: 1 | T34: =IF(ISNUMBER(S34),IF(S34>=1,1,0),"") -> 1 | U34: =IF(ISNUMBER(S34),IF(S34>=2,1,0),"") -> 0 | V34: 1 | W34: 0 | X34: A | Y34: https://newrelic.com/press-release/20230731 | Z34: Press release: 'values New Relic at an equity valuation of approximately $6.5 billion' (company-stated equity value; no EV stated). DEFM14A (https://www.sec.gov/Archives/edgar/data/1448056/000119312523241385/d484419ddefm14a.htm) states total funds required of ~$6.67bn and 71,020,661 shares outstanding at Sept 20, 2023 record date; Background/Qatalyst sections were beyond the fetchable portion so unaffected price, dollar VWAP and any May 2023 press-report unaffected date were NOT found; un_date is the last trading day before announcement used as the premium reference date, not a confirmed pre-leak date. Closing date 2023-11-08 per New Relic completion press release/8-K filed 2023-11-08. Q1 FY24 (Jun 30, 2023) 10-Q was filed after announcement so not used.
A35: P01 | B35: Splunk Inc. | C35: Cisco Systems | D35: 2023-09-21 | E35: strategic | F35: Infrastructure Software | G35: 157 | H35: 119.59 | I35: 29430.398 | J35: calculated_from_bridge | K35: 3843.3 | L35: 3038.704 | M35: 69.665 | N35: =IF(AND(ISNUMBER(I35),ISNUMBER(K35),K35>0),I35/K35,"") -> 7.6575854 | O35: =IF(AND(ISNUMBER(K35),ISNUMBER(L35),L35>0),K35/L35-1,"") -> 0.26478262 | P35: =IF(AND(ISNUMBER(M35),ISNUMBER(K35),K35>0),M35/K35,"") -> 0.01812635 | Q35: =IF(AND(ISNUMBER(I35),ISNUMBER(M35),M35>0),I35/M35,"") -> 422.45601 | R35: =IF(AND(ISNUMBER(G35),ISNUMBER(H35),H35>0),G35/H35-1,"") -> 0.3128188 | S35: 0 | T35: =IF(ISNUMBER(S35),IF(S35>=1,1,0),"") -> 0 | U35: =IF(ISNUMBER(S35),IF(S35>=2,1,0),"") -> 0 | V35: 1 | W35: 1 | X35: C | Y35: https://www.sec.gov/Archives/edgar/data/1353283/000110465923102594/tm2326347d1_ex99-1.htm | Z35: EV not stated by company; equity value ~$28bn rounded; debt = convertible notes carrying value; cash = cash + current investments at 2023-07-31 (10-Q). Premium and unaffected close from secondary press only.
A36: P04 | B36: Alteryx Inc. | C36: Clearlake Capital / Insight Partners | D36: 2023-12-18 | E36: sponsor | F36: Application Software | G36: 48.25 | I36: 4400 | J36: reported | K36: 920 | L36: 728.081 | N36: =IF(AND(ISNUMBER(I36),ISNUMBER(K36),K36>0),I36/K36,"") -> 4.7826087 | O36: =IF(AND(ISNUMBER(K36),ISNUMBER(L36),L36>0),K36/L36-1,"") -> 0.26359567 | P36: =IF(AND(ISNUMBER(M36),ISNUMBER(K36),K36>0),M36/K36,"") | Q36: =IF(AND(ISNUMBER(I36),ISNUMBER(M36),M36>0),I36/M36,"") | R36: =IF(AND(ISNUMBER(G36),ISNUMBER(H36),H36>0),G36/H36-1,"") | S36: 1 | T36: =IF(ISNUMBER(S36),IF(S36>=1,1,0),"") -> 1 | U36: =IF(ISNUMBER(S36),IF(S36>=2,1,0),"") -> 0 | V36: 1 | W36: 0 | X36: B | Y36: https://www.sec.gov/Archives/edgar/data/1689923/000119312523298609/d676158dex991.htm | Z36: EV $4.4bn stated 'including debt'; equity $3.46bn from Reuters (media). Debt/cash at 2023-09-30 are carrying values (convertible notes + term debt; cash + ST investments). Competing-bid claim by TechCrunch not confirmed.
A37: P05 | B37: Juniper Networks | C37: Hewlett Packard Enterprise | D37: 2024-01-09 | E37: strategic | G37: 40 | H37: 30.22 | I37: 14211.4 | J37: calculated_from_bridge | K37: 5648.5 | L37: 5152.3 | M37: 747.6 | N37: =IF(AND(ISNUMBER(I37),ISNUMBER(K37),K37>0),I37/K37,"") -> 2.51596 | O37: =IF(AND(ISNUMBER(K37),ISNUMBER(L37),L37>0),K37/L37-1,"") -> 0.096306504 | P37: =IF(AND(ISNUMBER(M37),ISNUMBER(K37),K37>0),M37/K37,"") -> 0.13235372 | Q37: =IF(AND(ISNUMBER(I37),ISNUMBER(M37),M37>0),I37/M37,"") -> 19.009363 | R37: =IF(AND(ISNUMBER(G37),ISNUMBER(H37),H37>0),G37/H37-1,"") -> 0.32362674 | T37: =IF(ISNUMBER(S37),IF(S37>=1,1,0),"") | U37: =IF(ISNUMBER(S37),IF(S37>=2,1,0),"") | V37: 0 | W37: 0 | X37: C | Y37: https://hpe.com/us/en/newsroom/press-release/2024/01/hpe-to-acquire-juniper-networks-to-accelerate-ai-driven-innovation.html | Z37: Sector set to Hardware OEM (networking equipment) = outside Phase 1 primary sectors; kept in raw data so the frozen exclusion rule is exercised. vwap_30 field holds the DEFM14A one-month VWAP 29.45. Equity value ~$14bn is HPE's rounded figure (shares x price ~ $12.97bn); long-term debt only.
A38: L40 | B38: Ansys | C38: Synopsys | D38: 2024-01-16 | E38: strategic | F38: Application Software | G38: 390.19 | I38: 35000 | J38: reported | K38: 2158.956 | L38: 2027.105 | M38: 680.576 | N38: =IF(AND(ISNUMBER(I38),ISNUMBER(K38),K38>0),I38/K38,"") -> 16.211539 | O38: =IF(AND(ISNUMBER(K38),ISNUMBER(L38),L38>0),K38/L38-1,"") -> 0.065043991 | P38: =IF(AND(ISNUMBER(M38),ISNUMBER(K38),K38>0),M38/K38,"") -> 0.31523384 | Q38: =IF(AND(ISNUMBER(I38),ISNUMBER(M38),M38>0),I38/M38,"") -> 51.427027 | R38: =IF(AND(ISNUMBER(G38),ISNUMBER(H38),H38>0),G38/H38-1,"") | S38: 0 | T38: =IF(ISNUMBER(S38),IF(S38>=1,1,0),"") -> 0 | U38: =IF(ISNUMBER(S38),IF(S38>=2,1,0),"") -> 0 | V38: 1 | W38: 0 | X38: B | Y38: https://news.synopsys.com/2024-01-16-Synopsys-to-Acquire-Ansys,-Creating-a-Leader-in-Silicon-to-Systems-Design-Solutions | Z38: Consideration $197.00 cash + 0.3450 SNPS shares per Ansys share. Offer price 390.19 = DEFM14A implied value on SNPS $559.96 close of Dec 21, 2023 (premium basis); on Jan 12, 2024 close ($494.40) implied value was $367.57. EV approx $35bn stated by Synopsys. Ansys unaffected dollar price and equity value not found. DEFM14A: 87,299,981 basic shares at record date. Close date July 17, 2025 per Synopsys completion release (search listing).
A39: L27 | B39: Everbridge, Inc. | C39: Thoma Bravo | D39: 2024-02-05 | E39: sponsor | F39: Application Software | G39: 35 | J39: undisclosed | K39: 450.158 | L39: 417.59 | M39: 6.343 | N39: =IF(AND(ISNUMBER(I39),ISNUMBER(K39),K39>0),I39/K39,"") | O39: =IF(AND(ISNUMBER(K39),ISNUMBER(L39),L39>0),K39/L39-1,"") -> 0.077990373 | P39: =IF(AND(ISNUMBER(M39),ISNUMBER(K39),K39>0),M39/K39,"") -> 0.014090608 | Q39: =IF(AND(ISNUMBER(I39),ISNUMBER(M39),M39>0),I39/M39,"") | R39: =IF(AND(ISNUMBER(G39),ISNUMBER(H39),H39>0),G39/H39-1,"") | S39: 0 | T39: =IF(ISNUMBER(S39),IF(S39>=1,1,0),"") -> 0 | U39: =IF(ISNUMBER(S39),IF(S39>=2,1,0),"") -> 0 | V39: 0 | W39: 0 | X39: A | Y39: https://www.thomabravo.com/press-releases/everbridge-enters-into-amended-merger-agreement-with-thoma-bravo | Z39: Original merger agreement dated 2024-02-04 (announced 2024-02-05) at $28.60/share (implied by the March 1 release: $35.00 is '$6.40 per share higher'); amended 2024-03-01 to $35.00 (final). ann uses the original announcement; premium reference date 2024-02-02 is from the original. March 1 release: 'values Everbridge at approximately $1.8 billion' (equity vs EV not specified; a Cooley-hosted copy mentions $1.5bn only in its URL slug). LTM based on last quarter reported before the Feb 5 announcement (Q3 2023); FY2023 10-K was filed 2024-02-27 (before the amendment): FY23 revenue 448,788k, op loss (61,399)k, D&A 58,815k. 41,462,726 shares outstanding at Mar 19, 2024 record date (DEFM14A https://www.sec.gov/Archives/edgar/data/1437352/000119312524073284/d809325ddefm14a.htm). Close date 2024-07-01 from Business Wire release 'Thoma Bravo Completes Acquisition of Everbridge' (date inferred from URL 20240701).
A40: L48 | B40: Model N | C40: Vista Equity Partners | D40: 2024-04-08 | E40: sponsor | F40: Application Software | G40: 30 | H40: 27.09 | J40: undisclosed | K40: 253.8 | M40: 4.677 | N40: =IF(AND(ISNUMBER(I40),ISNUMBER(K40),K40>0),I40/K40,"") | O40: =IF(AND(ISNUMBER(K40),ISNUMBER(L40),L40>0),K40/L40-1,"") | P40: =IF(AND(ISNUMBER(M40),ISNUMBER(K40),K40>0),M40/K40,"") -> 0.018427896 | Q40: =IF(AND(ISNUMBER(I40),ISNUMBER(M40),M40>0),I40/M40,"") | R40: =IF(AND(ISNUMBER(G40),ISNUMBER(H40),H40>0),G40/H40-1,"") -> 0.10741971 | S40: 0 | T40: =IF(ISNUMBER(S40),IF(S40>=1,1,0),"") -> 0 | U40: =IF(ISNUMBER(S40),IF(S40>=2,1,0),"") -> 0 | V40: 0 | W40: 1 | X40: A | Y40: https://www.sec.gov/Archives/edgar/data/1118417/000119312524089150/d766245dex991.htm ; https://www.sec.gov/Archives/edgar/data/1118417/000119312524138940/d823552ddefm14a.htm ; https://www.sec.gov/Archives/edgar/data/1118417/000119312524170493/d796513d8k.htm | Z40: Press release: 'all-cash transaction valued at approximately $1.25 billion' - not labeled equity vs enterprise (htype set to consideration); no EV/equity value stated. DEFM14A also cites ~17% premium to 90-trading-day VWAP of closing prices $25.62 (not 30-day) so vwap null. 39,422,997 basic shares at 2024-05-08 record date; diluted count not found. Unaffected date chosen as last trading day before announcement (filing doesn't use the word 'unaffected'). Closed 2024-06-27 per 8-K Item 2.01.
...

Sheet Summary
A1: Summary - live formulas from Deal_Dataset
A3: Deals in dataset | B3: =COUNTA(Deal_Dataset!$A$2:$A$56) -> 55
A4: Deals in EV/Revenue sample | B4: =SUM(Deal_Dataset!$V$2:$V$56) -> 35
A5: Deals in takeover-premium sample | B5: =SUM(Deal_Dataset!$W$2:$W$56) -> 20
A6: Broad-AI deals in EV/Rev sample | B6: =COUNTIFS(Deal_Dataset!$V$2:$V$56,1,Deal_Dataset!$T$2:$T$56,1) -> 11
A7: Strict-AI deals in EV/Rev sample | B7: =COUNTIFS(Deal_Dataset!$V$2:$V$56,1,Deal_Dataset!$U$2:$U$56,1) -> 2
A9: Mean EV/Revenue - broad AI (x) | B9: =AVERAGEIFS(Deal_Dataset!$N$2:$N$56,Deal_Dataset!$V$2:$V$56,1,Deal_Dataset!$T$2:$T$56,1) -> 8.2158659
A10: Mean EV/Revenue - non-AI (x) | B10: =AVERAGEIFS(Deal_Dataset!$N$2:$N$56,Deal_Dataset!$V$2:$V$56,1,Deal_Dataset!$T$2:$T$56,0) -> 9.9385656
A11: Mean EV/Revenue - all sample (x) | B11: =AVERAGEIFS(Deal_Dataset!$N$2:$N$56,Deal_Dataset!$V$2:$V$56,1) -> 9.3971457
A12: Mean revenue growth - broad AI | B12: =AVERAGEIFS(Deal_Dataset!$O$2:$O$56,Deal_Dataset!$V$2:$V$56,1,Deal_Dataset!$T$2:$T$56,1) -> 0.14421654
A13: Mean revenue growth - non-AI | B13: =AVERAGEIFS(Deal_Dataset!$O$2:$O$56,Deal_Dataset!$V$2:$V$56,1,Deal_Dataset!$T$2:$T$56,0) -> 0.23467949
A14: Mean 1-day premium - broad AI | B14: =AVERAGEIFS(Deal_Dataset!$R$2:$R$56,Deal_Dataset!$W$2:$W$56,1,Deal_Dataset!$T$2:$T$56,1) -> 0.33815777
A15: Mean 1-day premium - non-AI | B15: =AVERAGEIFS(Deal_Dataset!$R$2:$R$56,Deal_Dataset!$W$2:$W$56,1,Deal_Dataset!$T$2:$T$56,0) -> 0.32622472
A17: Medians (computed in Python; values)
A18: Median EV/Revenue - broad AI (x) | B18: 7.5071455
A19: Median EV/Revenue - non-AI (x) | B19: 7.997394
A20: Median 1-day premium - broad AI | B20: 0.35168436
A21: Median 1-day premium - non-AI | B21: 0.27741776
A23: Means are sensitive to outliers (e.g., Slack 36x); medians are the preferred comparison. Unadjusted - not an 'AI premium'.

Sheet AI_Coding
A1: Company | B1: Announced | C1: Coder 1 | D1: Coder 2 | E1: Agree? | F1: Final | G1: Subsector | H1: Coder 1 rationale | I1: Coder 2 rationale | J1: Adjudication
A2: Altair Engineering | B2: 2024-10-30 | C2: 1 | D2: 1 | E2: =IF(C2=D2,"Yes","No") -> Yes | F2: 1 | H2: Altair’s pre-deal portfolio included AI/data science, MLOps, AutoML and machine-learning workflows, but simulation/design and HPC remained major products that function without ML. AI was an important capability and product line, not clearly the defining target-level product. | I2: The FY2023 filing documents dedicated AI/data-science and ML workflow offerings alongside simulation, design and HPC. Because the overall suite is broader than AI and no AI-specific revenue split is documented, intensity is 1. | J2: Coders agreed on intensity; coder 1 values recorded as final (procedural, no disagreement to resolve).
A3: Alteryx Inc. | B3: 2023-12-18 | C3: 1 | D3: 1 | E3: =IF(C3=D3,"Yes","No") -> Yes | F3: 1 | H3: Alteryx offered ML/AutoML, NLP, OCR, model training/explainability and AI-driven insight products before the deal. These are commercial capabilities within a broader analytics-automation platform; data preparation and workflow automation still function without ML, and no AI-specific revenue split was documented. | I3: The 2022 Form 10-K and 2021 product announcement document ML modeling, AutoML and NLP/computer-vision features. They establish an AI-enabled offering and persistence, but not that the whole platform is AI-native or that AI represents material standalone revenue. | J3: Coders agreed on intensity; coder 1 values recorded as final (procedural, no disagreement to resolve).
A4: Couchbase | B4: 2025-06-20 | C4: 1 | D4: 1 | E4: =IF(C4=D4,"Yes","No") -> Yes | F4: 1 | H4: Couchbase Server 7.6 added vector search and integrations for semantic search/RAG in March 2024, more than 12 months before the announcement. The main NoSQL database remains useful without AI, and the documented workflow uses chosen external embedding models/LLMs rather than Couchbase’s own trained models. | I4: Pre-deal technical documentation shows vector indexing and AI-application integrations, so AI enabled some use cases and passes persistence. The primary product is still a general-purpose operational database, not an AI model or AI-specific infrastructure platform. | J4: Coders agreed on intensity; coder 1 values recorded as final (procedural, no disagreement to resolve).
A5: Cvent Inc | B5: 2016-04-18 | C5: 0 | D5: 0 | E5: =IF(C5=D5,"Yes","No") -> Yes | F5: 0 | H5: Cvent’s pre-deal Form 10-K describes Event Cloud and Hospitality Cloud products for event planning, registration, venue sourcing and event management. The reviewed contemporaneous disclosure does not identify AI/ML as a core or enabling product feature. | I5: At the April 2016 announcement date, Cvent was a cloud event/hospitality management platform; the referenced annual report does not document model-dependent products, AI technical assets or AI-linked revenue. | J5: Coders agreed on intensity; coder 1 values recorded as final (procedural, no disagreement to resolve).
A6: Duck Creek Technologies, Inc. | B6: 2023-01-09 | C6: 0 | D6: 0 | E6: =IF(C6=D6,"Yes","No") -> Yes | F6: 0 | H6: The pre-deal 2022 Form 10-K describes cloud SaaS core systems for insurance policy administration, billing, claims, rating and underwriting. The reviewed pre-announcement evidence does not document AI/ML as a product dependency, proprietary AI asset or material revenue driver. | I6: Duck Creek’s pre-announcement disclosures center on configurable SaaS insurance operations and core systems, not model-based products. References to data insights do not by themselves establish AI, and no qualifying AI asset or revenue evidence was found. | J6: Coders agreed on intensity; coder 1 values recorded as final (procedural, no disagreement to resolve).
A7: Envestnet | B7: 2024-07-11 | C7: 0 | D7: 0 | E7: =IF(C7=D7,"Yes","No") -> Yes | F7: 0 | H7: Envestnet’s FY2023 Form 10-K describes wealth-management technology, financial planning, asset allocation, portfolio tools, data aggregation and analytics. The filing does not document AI/ML as a product dependency or identify proprietary models/material AI revenue, so generic ‘intelligence’ and analytics language is not enough to code AI. | I7: The pre-announcement disclosure centers on advisor software, portfolio construction/rebalancing, financial data and analytics. No specific pre-deal ML model or AI-native product was established from the reviewed source, so the conservative intensity is 0. | J7: Coders agreed on intensity; coder 1 values recorded as final (procedural, no disagreement to resolve).
A8: Informatica | B8: 2025-05-27 | C8: 1 | D8: 1 | E8: =IF(C8=D8,"Yes","No") -> Yes | F8: 1 | H8: Informatica’s CLAIRE engine applied metadata-driven AI and machine learning to recommendations and automation in data management. The main platform remained broader data integration, governance and quality software, so AI enabled the product rather than defining the whole company’s core function. | I8: A 2017 company announcement documents CLAIRE as a proprietary metadata-driven AI technology using ML. However, Informatica sold a broad data-management platform that would remain useful without CLAIRE, and AI-specific revenue was not reported. | J8: Coders agreed on intensity; coder 1 values recorded as final (procedural, no disagreement to resolve).
